Workbook

Sheet README
A1: Circular Design Advisor – Life Cycle Inventory (LCI)
A2: One modular aluminium exhibition-booth panel · five end-of-life / circular strategies · formula-driven
A4: Goal and scope
A5: Functional unit | B5: ONE USE of one panel at one exhibition event (per use). Lifetime burdens are divided by the expected number of uses.
A6: Reference flow | B6: 1 panel of the selected design (mass from Product_Design), over its expected service life.
A7: System boundary | B7: Cradle-to-grave: panel production (metal + fabrication), transport to/from events, cleaning, repair, reprocessing, end-of-life transport, sorting, waste-to-energy; recycling credit (net scrap) or cut-off.
A8: Impact category | B8: Climate change (GWP100, kg CO2e) only. Costs are a proxy in EUR.
A9: Multifunctionality | B9: Net-scrap method (default): credit only for recovered metal beyond the recycled input share, valued at (EF primary − EF secondary). Cut-off: no credit. Switch on the Context sheet.
A10: Geography / time | B10: Europe / Germany, 2023–2025 data (see Parameters).
A12: Workbook map
A13: Parameters | B13: All 30 model parameters with value, range, unit, data type, quality score (1–5), source and URL. Edit column C (blue) to change the model.
A14: Product_Design / Strategies / Business_Models | B14: Design archetypes, strategy settings and business-model behaviour (all flagged assumptions).
A15: Context | B15: Decision context: design, business model, planned uses, event and end-of-life distances, credit method (yellow cells). Also derived global factors.
A16: Calc | B16: Per-strategy intermediate quantities: planned uses, loss probability, expected uses, repair events, recovery yield, credit mass.
A17: LCI | B17: THE INVENTORY: every foreground flow (kg, kWh, t·km) per panel life and per functional unit, with an indicative background dataset for Brightway/ecoinvent mapping.
A18: LCIA_GWP | B18: LCI per functional unit × emission factor = kg CO2e per use, by flow and by life-cycle stage.
A19: Cost | B19: Cost inventory per panel life and per use (EUR, incl. business-model margin).
A20: KPIs | B20: Climate, cost, circularity (simplified MCI), material recovery, virgin Al, feasibility, weighted score, rank and recommendation.
A21: Validation | B21: Excel KPIs vs Python model (src/cirdesign/model.py) at the default context. All rows should read OK.
A23: Colour legend
A24: Blue text | B24: Hard-coded input – edit these.
A25: Yellow fill | B25: Key decision levers (Context sheet).
A26: Green text | B26: Link to another sheet.
A27: Black text | B27: Formula – do not overwrite.
A29: Important
A30: Data status | B30: Only 6 of the model inputs come from literature or public databases; the rest are author assumptions (type = assumption, quality 2). Results illustrate the method, not a real product. Do not cite the numbers.
A31: Regenerate | B31: python scripts/build_lci_workbook.py (rebuilds this file from data/*.csv; open in Excel to recalculate).

Sheet Parameters
A1: Parameters
A2: Source: data/literature_sources.csv. Column C is the value used by the model; edit it to run a scenario. Low/High = literature or assumed range.
A4: ID (named range) | B4: Parameter | C4: Value | D4: Low | E4: High | F4: Unit | G4: Type | H4: Used in model | I4: Quality (1–5) | J4: Source | K4: Year | L4: URL | M4: Note
A5: ef_primary | B5: Primary aluminium, cradle-to-gate (default: European average) | C5: 6.3 | D5: 4 | E5: 14.8 | F5: kg CO2e/kg | G5: literature | H5: =TRUE() -> TRUE | I5: 4 | J5: European Aluminium, Environmental Profile Report 2024 (press release 6 Nov 2024) | K5: 2023 | L5: https://european-aluminium.eu/wp-content/uploads/2024/11/06-11-24-European-Aluminium-Environmental-Profile-Report-launch-PR.pdf | M5: European primary aluminium 6.3 kg CO2 per kg in 2023 (6.7 in 2015). Range: lower bound from Hydro (hydropower-based regions, below 4); upper bound = IAI global average.
A6: ef_primary_global | B6: Primary aluminium, global average | C6: 14.8 | F6: kg CO2e/kg | G6: literature | H6: =FALSE() -> FALSE | I6: 4 | J6: International Aluminium Institute, GHG emissions intensity release (Dec 2024) | K6: 2023 | L6: https://international-aluminium.org/global-aluminium-industry-greenhouse-gas-emissions-intensity-reduction-continues-with-total-emissions-below-2020-peak | M6: 14.8 t CO2e per t primary aluminium in 2023. Used as the upper bound of ef_primary.
A7: ef_secondary | B7: Recycled (secondary) aluminium from post-consumer scrap | C7: 0.5 | D7: 0.4 | E7: 0.9 | F7: kg CO2e/kg | G7: literature | H7: =TRUE() -> TRUE | I7: 3 | J7: Hydro, 'Carbon footprint of recycled aluminium' (via climateaction.org) | K7: 2021 | L7: https://climateaction.org/news/carbon-footprint-of-recycled-aluminium | M7: Approximately 0.5 t CO2e per t for the recycling process, post-consumer scrap. Range is an assumption.
A8: grid_ef | B8: German electricity mix | C8: 0.344 | D8: 0.1 | E8: 0.45 | F8: kg CO2e/kWh | G8: database | H8: =TRUE() -> TRUE | I8: 4 | J8: Umweltbundesamt (UBA), CO2-Emissionen pro Kilowattstunde Strom 2025 (page dated 23 Mar 2026) | K8: 2025 | L8: https://www.umweltbundesamt.de/themen/co2-emissionen-pro-kilowattstunde-strom-2025-nur | M8: 344 g CO2/kWh for 2025 (estimate); 353 g for 2024 (preliminary). Range lower bound = a decarbonised mix (assumption).
A9: transport_ef | B9: Road freight, articulated truck <40 t, diesel, per tonne-km (full load) | C9: 0.058 | D9: 0.058 | E9: 0.562 | F9: kg CO2e/(t*km) | G9: database | H9: =TRUE() -> TRUE | I9: 3 | J9: GLEC Framework v3.0 default (via Climatiq); upper bound BEIS/DEFRA 2022 rigid HGV 3.5-7.5 t average laden | K9: 2023 | L9: https://www.climatiq.io/data/emission-factor/551e7a49-d6c2-4def-9db3-e9e98dc03da4 | M9: Climatiq lists the GLEC factor as deprecated (superseded by a newer release); re-check before real use. Upper bound 0.562 (BEIS 2022, fuel combustion only) represents small partly loaded vehicles.
A10: transport_load_factor | B10: Average load factor of exhibition transport | C10: 0.6 | D10: 0.4 | E10: 0.9 | F10: share | G10: assumption | H10: =TRUE() -> TRUE | I10: 2 | J10: Author assumption | M10: Panels are rarely shipped in full trucks; effective factor = EF / load factor.
A11: lme_price_usd_t | B11: LME aluminium price | C11: 3100 | D11: 2500 | E11: 3500 | F11: USD/t | G11: database | H11: =TRUE() -> TRUE | I11: 2 | J11: alcircle market report, LME aluminium offer price at October start (about 3,109.5 USD/t) | L11: https://www.alcircle.com/news/lme-aluminium-offer-price-eases-0-34-to-3-109-5-t-at-october-start-as-stocks-dip-to-240-625t-121420 | M11: Article could not be re-fetched to confirm its year; treat as approximate. Check the LME for a current price.
A12: usd_eur | B12: USD to EUR conversion | C12: 0.9 | D12: 0.85 | E12: 0.95 | F12: EUR/USD | G12: assumption | H12: =TRUE() -> TRUE | I12: 2 | J12: Author assumption | M12: Fixed conversion for the cost proxy.
A13: scrap_price_ratio | B13: Scrap price as share of LME price | C13: 0.7 | D13: 0.55 | E13: 0.85 | F13: share | G13: assumption | H13: =TRUE() -> TRUE | I13: 2 | J13: Author assumption | M13: Typical discount of aluminium scrap to LME; not verified against a price series.
A14: collection_rate | B14: Collection rate of aluminium at end of life | C14: 0.95 | D14: 0.8 | E14: 0.99 | F14: share | G14: literature | H14: =TRUE() -> TRUE | I14: 4 | J14: European Aluminium, 'Collection of aluminium building products at their end-of-life' | K14: 2004 study | L14: https://european-aluminium.eu/blog/collection-of-aluminium-building-products-at-their-end-of-life/ | M14: More than 95 % collection in 9 studied buildings; 98.3 % (Germany) and 99.3 % (Netherlands) case studies. Building products, applied here to booth panels as a proxy.
A15: melt_yield | B15: Metal yield of remelting | C15: 0.95 | D15: 0.9 | E15: 0.98 | F15: share | G15: assumption | H15: =TRUE() -> TRUE | I15: 2 | J15: Author assumption | M15: Share of collected metal that leaves the remelter as usable metal.
A16: recycled_content | B16: Recycled content of new panels | C16: 0.3 | D16: 0.1 | E16: 0.6 | F16: share | G16: assumption | H16: =TRUE() -> TRUE | I16: 2 | J16: Author assumption | M16: Share of secondary aluminium in new extrusions.
A17: e_fab | B17: Fabrication energy (cutting, machining, surface finish) | C17: 1.5 | D17: 0.8 | E17: 3 | F17: kWh/kg | G17: assumption | H17: =TRUE() -> TRUE | I17: 2 | J17: Author assumption | M17: Electricity per kg of panel; scaled by a design factor.
A18: sort_energy | B18: Dismantling and sorting energy before remelting | C18: 0.15 | D18: 0.05 | E18: 0.3 | F18: kWh/kg | G18: assumption | H18: =TRUE() -> TRUE | I18: 2 | J18: Author assumption
A19: disposal_ef | B19: Waste-to-energy process burden for aluminium | C19: 0.02 | D19: 0.01 | E19: 0.05 | F19: kg CO2e/kg | G19: assumption | H19: =TRUE() -> TRUE | I19: 2 | J19: Author assumption
A20: disposal_recovery | B20: Metal recovered from incineration bottom ash | C20: 0.2 | D20: 0.1 | E20: 0.5 | F20: share | G20: assumption | H20: =TRUE() -> TRUE | I20: 2 | J20: Author assumption | M20: Under net-scrap crediting this earns no credit when it is below the recycled content.
A21: damage_rate | B21: Panel loss rate per event from handling damage | C21: 0.08 | D21: 0.02 | E21: 0.25 | F21: probability per event | G21: assumption | H21: =TRUE() -> TRUE | I21: 2 | J21: Author assumption | M21: Main uncertainty: no published damage rate for exhibition panels was found.
A22: e_clean | B22: Cleaning and inspection energy per reuse event | C22: 0.05 | D22: 0.02 | E22: 0.15 | F22: kWh/kg | G22: assumption | H22: =TRUE() -> TRUE | I22: 2 | J22: Author assumption
A23: e_repair | B23: Repair energy per repair | C23: 0.3 | D23: 0.15 | E23: 0.6 | F23: kWh/kg | G23: assumption | H23: =TRUE() -> TRUE | I23: 2 | J23: Author assumption
A24: repair_share | B24: Replacement material per repair (share of mass) | C24: 0.1 | D24: 0.03 | E24: 0.25 | F24: share | G24: assumption | H24: =TRUE() -> TRUE | I24: 2 | J24: Author assumption
A25: e_reprocess | B25: Reprocessing energy per event (stripping, re-finishing) | C25: 0.8 | D25: 0.4 | E25: 1.5 | F25: kWh/kg | G25: assumption | H25: =TRUE() -> TRUE | I25: 2 | J25: Author assumption
A26: manuf_cost | B26: Manufacturing cost on top of metal | C26: 8 | D26: 5 | E26: 12 | F26: EUR/kg | G26: assumption | H26: =TRUE() -> TRUE | I26: 2 | J26: Author assumption | M26: Extrusion, machining and finishing.
A27: handling_cost | B27: Set-up and dismantling labour per event | C27: 6 | D27: 3 | E27: 10 | F27: EUR/panel/event | G27: assumption | H27: =TRUE() -> TRUE | I27: 2 | J27: Author assumption
A28: storage_cost | B28: Storage per panel between events | C28: 3 | D28: 1 | E28: 6 | F28: EUR/panel/event | G28: assumption | H28: =TRUE() -> TRUE | I28: 2 | J28: Author assumption
A29: labour_rate | B29: Workshop labour rate | C29: 45 | D29: 35 | E29: 60 | F29: EUR/h | G29: assumption | H29: =TRUE() -> TRUE | I29: 2 | J29: Author assumption
A30: transport_cost | B30: Freight cost per tonne-km | C30: 0.25 | D30: 0.15 | E30: 0.6 | F30: EUR/(t*km) | G30: assumption | H30: =TRUE() -> TRUE | I30: 2 | J30: Author assumption
A31: gate_fee | B31: Disposal gate fee | C31: 0.15 | D31: 0.08 | E31: 0.3 | F31: EUR/kg | G31: assumption | H31: =TRUE() -> TRUE | I31: 2 | J31: Author assumption
A32: material_loop_ref | B32: Reference share of booth mass that can be materially recovered | C32: 0.7 | F32: share | G32: literature | H32: =FALSE() -> FALSE | I32: 3 | J32: AUMA, Guide Resource Management for trade fairs, section 7.1, p. 40 | K32: 2026 | L32: https://www.auma.de/fileadmin/publikationen/guide-resource-management-auma-fwd-2026-v1-0.pdf | M32: 'A reference value here is 70 %.' Used as a benchmark line for material recovery.
A33: validation_reuse_vs_recycling | B33: Published reduction of net GWP, direct reuse vs recycling (aluminium portal-frame tent) | C33: -0.22 | F33: share | G33: literature | H33: =FALSE() -> FALSE | I33: 4 | J33: Skejic, Antic, Carevic, Gkantou, Buildings 16(13):2610 (DOI 10.3390/buildings16132610) | K33: 2026 | L33: https://www.citedrive.com/en/discovery/reuse-of-aluminium-structural-components-in-circular-construction-a-life-cycle-assessment-of-a-portal-frame-tent-structure/ | M33: 'Direct reuse lowers the net global warming potential by about 22 % relative to recycling.' Different system (EN 15804, modules A-D), so used only as a plausibility check.
A34: context_stand_footprint | B34: Footprint of a reusable zero-waste exhibition stand (context) | C34: 1.4 | F34: t CO2e | G34: literature | H34: =FALSE() -> FALSE | I34: 2 | J34: ISLA, 'Measuring our reusable, zero waste exhibition stand' (company blog) | K34: 2024 | L34: https://weareisla.co.uk/2024/08/20/measuring-our-reusable-zero-waste-exhibition-stand/ | M34: 1.4 tonnes CO2e from production to arrival at the event. Context only; not used in the model.

Sheet Product_Design
A1: design | B1: name | C1: mass_kg | D1: repairability | E1: fab_factor | F1: cost_factor | G1: damage_mult | H1: technical_lifetime_events | I1: disassembly | J1: note
A2: A | B2: Welded frame panel | C2: 14 | D2: 0.3 | E2: 1 | F2: 0.85 | G2: 1 | H2: 15 | I2: 0.3 | J2: Design archetype (assumed): cheap, hard to repair
A3: B | B3: Screwed modular panel | C3: 12 | D3: 0.9 | E3: 1.15 | F3: 1.1 | G3: 0.9 | H3: 40 | I3: 0.9 | J3: Design archetype (assumed): bolted joints, replaceable parts
A4: C | B4: Clip-fit lightweight panel | C4: 8.5 | D4: 0.55 | E4: 1.05 | F4: 1 | G4: 1.3 | H4: 20 | I4: 0.6 | J4: Design archetype (assumed): light but more fragile
A6: Source: data/product_data.csv. Design archetypes are assumptions.

Sheet Strategies
A1: strategy | B1: label | C1: family | D1: feasibility_base | E1: clean_kwh_per_kg | F1: repair | G1: reprocess | H1: damage_factor | I1: labour_h | J1: note
A2: reuse | B2: Direct reuse | C2: reuse | D2: 0.85 | E2: 0.05 | F2: 0 | G2: 0 | H2: 1 | I2: 0.05 | J2: Inspect, clean, redeploy
A3: repair | B3: Repair and reuse | C3: reuse | D3: 0.75 | E3: 0.05 | F3: 1 | G3: 0 | H3: 1 | I3: 0.4 | J3: Damaged repairable panels are fixed, others scrapped
A4: reprocessing | B4: Reprocessing | C4: reuse | D4: 0.65 | E4: 0.05 | F4: 0 | G4: 1 | H4: 0.6 | I4: 0.25 | J4: Strip and re-finish each time; fewer cumulative damage losses (assumed)
A5: recycling | B5: Recycling | C5: single | D5: 0.9 | E5: 0 | F5: 0 | G5: 0 | H5: 1 | I5: 0 | J5: Single use then remelting
A6: disposal | B6: Disposal | C6: single | D6: 1 | E6: 0 | F6: 0 | G6: 0 | H6: 1 | I6: 0 | J6: Single use then waste-to-energy
A8: Source: data/strategies.csv. repair / reprocess are 0/1 switches. Row order fixes the strategy columns on every other sheet.

Sheet Business_Models
A1: name | B1: kind | C1: label | D1: redeploy | E1: margin | F1: damage_mult | G1: note
A2: sale | B2: business_model | C2: Sale | D2: 0.7 | E2: 0 | F2: 1 | G2: Owner decides whether to redeploy (assumed redeployment probability per event)
A3: rental | B3: business_model | C3: Rental | D3: 0.95 | E3: 0.2 | F3: 1 | G3: Provider retains ownership and collects panels (assumed)
A4: paas | B4: business_model | C4: Product-as-a-service | D4: 0.98 | E4: 0.25 | F4: 0.85 | G4: Provider maintains panels; fewer handling losses (assumed)
A6: Source: data/business_models.csv (all assumed).

Sheet Context
A1: Decision context and derived global factors
A2: Yellow cells are the levers. Defaults reproduce the README baseline (design B, rental, 6 planned uses, 400 km).
A4: Setting | B4: Value | C4: Unit | D4: Note
A5: Panel design | B5: B | D5: A, B or C (Product_Design)
A6: Business model | B6: rental | D6: sale, rental or paas (Business_Models)
A7: Planned uses (reuse strategies) | B7: 6 | C7: events | D7: Capped at the design's technical lifetime
A8: Distance to each event (one way) | B8: 400 | C8: km | D8: Reuse routes travel out and back each event
A9: Distance to end-of-life facility | B9: 100 | C9: km
A10: Recycling credit method | B10: net_scrap | D10: net_scrap or cut_off
A12: Selected design and business-model attributes
A13: Panel mass | B13: =INDEX(Product_Design!$C$2:$C$4,MATCH(ctx_design,Product_Design!$A$2:$A$4,0)) -> 12 | C13: kg
A14: Repairability | B14: =INDEX(Product_Design!$D$2:$D$4,MATCH(ctx_design,Product_Design!$A$2:$A$4,0)) -> 0.9 | C14: share
A15: Fabrication energy factor | B15: =INDEX(Product_Design!$E$2:$E$4,MATCH(ctx_design,Product_Design!$A$2:$A$4,0)) -> 1.15 | C15: ×
A16: Manufacturing cost factor | B16: =INDEX(Product_Design!$F$2:$F$4,MATCH(ctx_design,Product_Design!$A$2:$A$4,0)) -> 1.1 | C16: ×
A17: Design damage multiplier | B17: =INDEX(Product_Design!$G$2:$G$4,MATCH(ctx_design,Product_Design!$A$2:$A$4,0)) -> 0.9 | C17: ×
A18: Technical lifetime | B18: =INDEX(Product_Design!$H$2:$H$4,MATCH(ctx_design,Product_Design!$A$2:$A$4,0)) -> 40 | C18: events
A19: Disassembly score | B19: =INDEX(Product_Design!$I$2:$I$4,MATCH(ctx_design,Product_Design!$A$2:$A$4,0)) -> 0.9 | C19: share
A20: Redeployment probability per event | B20: =INDEX(Business_Models!$D$2:$D$4,MATCH(ctx_bm,Business_Models!$A$2:$A$4,0)) -> 0.95 | C20: share
A21: Business-model margin | B21: =INDEX(Business_Models!$E$2:$E$4,MATCH(ctx_bm,Business_Models!$A$2:$A$4,0)) -> 0.2 | C21: share
A22: Business-model damage multiplier | B22: =INDEX(Business_Models!$F$2:$F$4,MATCH(ctx_bm,Business_Models!$A$2:$A$4,0)) -> 1 | C22: ×
A24: Derived global factors
A25: Aluminium input mix factor | B25: =(1-recycled_content)*ef_primary+recycled_content*ef_secondary -> 4.56 | C25: kg CO2e/kg | D25: Recycled-content weighted mix of primary and secondary Al
A26: Effective freight factor | B26: =transport_ef/transport_load_factor -> 0.096666667 | C26: kg CO2e/(t·km) | D26: Full-load factor divided by load factor
A27: Aluminium price | B27: =lme_price_usd_t*usd_eur/1000 -> 2.79 | C27: EUR/kg | D27: LME price converted to EUR
A28: Recovery yield, recycling route | B28: =collection_rate*melt_yield -> 0.9025 | C28: share | D28: Collection × remelting yield
A29: Credit factor (avoided primary) | B29: =ef_primary-ef_secondary -> 5.8 | C29: kg CO2e/kg | D29: Burden avoided per kg of secondary Al that replaces primary
A30: Distance penalty (feasibility) | B30: =MAX(0,1-ctx_event_km/2000) -> 0.8 | C30: share | D30: Linear penalty, zero at 2,000 km

Sheet Calc
A1: Per-strategy intermediate quantities
A2: Life-cycle logic per strategy (mirrors model.evaluate). Columns D:H follow the Strategies sheet order.
A4: Quantity | B4: Unit | C4: Formula / note | D4: =Strategies!A2 -> reuse | E4: =Strategies!A3 -> repair | F4: =Strategies!A4 -> reprocessing | G4: =Strategies!A5 -> recycling | H4: =Strategies!A6 -> disposal | I4: Basis / source
A5: Strategy settings (from Strategies sheet)
A6: Single-use route (1 = yes) | B6: flag | C6: family = single | D6: =IF(INDEX(Strategies!$C$2:$C$6,MATCH(D4,Strategies!$A$2:$A$6,0))="single",1,0) -> 0 | E6: =IF(INDEX(Strategies!$C$2:$C$6,MATCH(E4,Strategies!$A$2:$A$6,0))="single",1,0) -> 0 | F6: =IF(INDEX(Strategies!$C$2:$C$6,MATCH(F4,Strategies!$A$2:$A$6,0))="single",1,0) -> 0 | G6: =IF(INDEX(Strategies!$C$2:$C$6,MATCH(G4,Strategies!$A$2:$A$6,0))="single",1,0) -> 1 | H6: =IF(INDEX(Strategies!$C$2:$C$6,MATCH(H4,Strategies!$A$2:$A$6,0))="single",1,0) -> 1
A7: Repair switch | B7: flag | D7: =INDEX(Strategies!$F$2:$F$6,MATCH(D4,Strategies!$A$2:$A$6,0)) -> 0 | E7: =INDEX(Strategies!$F$2:$F$6,MATCH(E4,Strategies!$A$2:$A$6,0)) -> 1 | F7: =INDEX(Strategies!$F$2:$F$6,MATCH(F4,Strategies!$A$2:$A$6,0)) -> 0 | G7: =INDEX(Strategies!$F$2:$F$6,MATCH(G4,Strategies!$A$2:$A$6,0)) -> 0 | H7: =INDEX(Strategies!$F$2:$F$6,MATCH(H4,Strategies!$A$2:$A$6,0)) -> 0
A8: Reprocessing switch | B8: flag | D8: =INDEX(Strategies!$G$2:$G$6,MATCH(D4,Strategies!$A$2:$A$6,0)) -> 0 | E8: =INDEX(Strategies!$G$2:$G$6,MATCH(E4,Strategies!$A$2:$A$6,0)) -> 0 | F8: =INDEX(Strategies!$G$2:$G$6,MATCH(F4,Strategies!$A$2:$A$6,0)) -> 1 | G8: =INDEX(Strategies!$G$2:$G$6,MATCH(G4,Strategies!$A$2:$A$6,0)) -> 0 | H8: =INDEX(Strategies!$G$2:$G$6,MATCH(H4,Strategies!$A$2:$A$6,0)) -> 0
A9: Strategy damage factor | B9: × | D9: =INDEX(Strategies!$H$2:$H$6,MATCH(D4,Strategies!$A$2:$A$6,0)) -> 1 | E9: =INDEX(Strategies!$H$2:$H$6,MATCH(E4,Strategies!$A$2:$A$6,0)) -> 1 | F9: =INDEX(Strategies!$H$2:$H$6,MATCH(F4,Strategies!$A$2:$A$6,0)) -> 0.6 | G9: =INDEX(Strategies!$H$2:$H$6,MATCH(G4,Strategies!$A$2:$A$6,0)) -> 1 | H9: =INDEX(Strategies!$H$2:$H$6,MATCH(H4,Strategies!$A$2:$A$6,0)) -> 1
A10: Workshop labour per event | B10: h | D10: =INDEX(Strategies!$I$2:$I$6,MATCH(D4,Strategies!$A$2:$A$6,0)) -> 0.05 | E10: =INDEX(Strategies!$I$2:$I$6,MATCH(E4,Strategies!$A$2:$A$6,0)) -> 0.4 | F10: =INDEX(Strategies!$I$2:$I$6,MATCH(F4,Strategies!$A$2:$A$6,0)) -> 0.25 | G10: =INDEX(Strategies!$I$2:$I$6,MATCH(G4,Strategies!$A$2:$A$6,0)) -> 0 | H10: =INDEX(Strategies!$I$2:$I$6,MATCH(H4,Strategies!$A$2:$A$6,0)) -> 0
A11: Base feasibility | B11: share | D11: =INDEX(Strategies!$D$2:$D$6,MATCH(D4,Strategies!$A$2:$A$6,0)) -> 0.85 | E11: =INDEX(Strategies!$D$2:$D$6,MATCH(E4,Strategies!$A$2:$A$6,0)) -> 0.75 | F11: =INDEX(Strategies!$D$2:$D$6,MATCH(F4,Strategies!$A$2:$A$6,0)) -> 0.65 | G11: =INDEX(Strategies!$D$2:$D$6,MATCH(G4,Strategies!$A$2:$A$6,0)) -> 0.9 | H11: =INDEX(Strategies!$D$2:$D$6,MATCH(H4,Strategies!$A$2:$A$6,0)) -> 1
A12: Disposal route (1 = yes) | B12: flag | D12: =IF(D4="disposal",1,0) -> 0 | E12: =IF(E4="disposal",1,0) -> 0 | F12: =IF(F4="disposal",1,0) -> 0 | G12: =IF(G4="disposal",1,0) -> 0 | H12: =IF(H4="disposal",1,0) -> 1
A13: Service life
A14: Planned uses N | B14: events | C14: min(planned, technical lifetime) | D14: =IF(D6=1,1,MIN(ROUND(ctx_n,0),d_life)) -> 6 | E14: =IF(E6=1,1,MIN(ROUND(ctx_n,0),d_life)) -> 6 | F14: =IF(F6=1,1,MIN(ROUND(ctx_n,0),d_life)) -> 6 | G14: =IF(G6=1,1,MIN(ROUND(ctx_n,0),d_life)) -> 1 | H14: =IF(H6=1,1,MIN(ROUND(ctx_n,0),d_life)) -> 1
A15: Damage probability per event | B15: share | C15: damage_rate × design × business model × strategy | D15: =IF(D6=1,0,damage_rate*d_dmg*bm_dmg*D9) -> 0.072 | E15: =IF(E6=1,0,damage_rate*d_dmg*bm_dmg*E9) -> 0.072 | F15: =IF(F6=1,0,damage_rate*d_dmg*bm_dmg*F9) -> 0.0432 | G15: =IF(G6=1,0,damage_rate*d_dmg*bm_dmg*G9) -> 0 | H15: =IF(H6=1,0,damage_rate*d_dmg*bm_dmg*H9) -> 0
A16: Damage that ends the panel's life | B16: share | C16: repairable damage is fixed | D16: =IF(D7=1,D15*(1-d_repair),D15) -> 0.072 | E16: =IF(E7=1,E15*(1-d_repair),E15) -> 0.0072 | F16: =IF(F7=1,F15*(1-d_repair),F15) -> 0.0432 | G16: =IF(G7=1,G15*(1-d_repair),G15) -> 0 | H16: =IF(H7=1,H15*(1-d_repair),H15) -> 0
A17: Loss probability per event | B17: share | C17: damage loss or not redeployed | D17: =IF(D6=1,1,1-(1-D16)*bm_redeploy) -> 0.1184 | E17: =IF(E6=1,1,1-(1-E16)*bm_redeploy) -> 0.05684 | F17: =IF(F6=1,1,1-(1-F16)*bm_redeploy) -> 0.09104 | G17: =IF(G6=1,1,1-(1-G16)*bm_redeploy) -> 1 | H17: =IF(H6=1,1,1-(1-H16)*bm_redeploy) -> 1
A18: Expected uses U | B18: uses | C18: Σ_{k=0..N-1} (1-p)^k | D18: =IF(D6=1,1,IF(D17<=0.000000000001,MAX(D14,1),(1-(1-D17)^MAX(D14,1))/D17)) -> 4.4806301 | E18: =IF(E6=1,1,IF(E17<=0.000000000001,MAX(E14,1),(1-(1-E17)^MAX(E14,1))/E17)) -> 5.2093232 | F18: =IF(F6=1,1,IF(F17<=0.000000000001,MAX(F14,1),(1-(1-F17)^MAX(F14,1))/F17)) -> 4.7892531 | G18: =IF(G6=1,1,IF(G17<=0.000000000001,MAX(G14,1),(1-(1-G17)^MAX(G14,1))/G17)) -> 1 | H18: =IF(H6=1,1,IF(H17<=0.000000000001,MAX(H14,1),(1-(1-H17)^MAX(H14,1))/H17)) -> 1 | I18: Geometric survival over N planned events
A19: Reuse cycles (U − 1) | B19: cycles | D19: =D18-1 -> 3.4806301 | E19: =E18-1 -> 4.2093232 | F19: =F18-1 -> 3.7892531 | G19: =G18-1 -> 0 | H19: =H18-1 -> 0
A20: Repairs per event | B20: repairs/event | D20: =IF(AND(D6=0,D7=1),D15*d_repair,0) -> 0 | E20: =IF(AND(E6=0,E7=1),E15*d_repair,0) -> 0.0648 | F20: =IF(AND(F6=0,F7=1),F15*d_repair,0) -> 0 | G20: =IF(AND(G6=0,G7=1),G15*d_repair,0) -> 0 | H20: =IF(AND(H6=0,H7=1),H15*d_repair,0) -> 0
A21: Freight legs per event | B21: legs | C21: reuse: out and back | D21: =IF(D6=1,1,2) -> 2 | E21: =IF(E6=1,1,2) -> 2 | F21: =IF(F6=1,1,2) -> 2 | G21: =IF(G6=1,1,2) -> 1 | H21: =IF(H6=1,1,2) -> 1
A22: End of life
A23: Material recovery yield | B23: share | C23: bottom-ash recovery for disposal | D23: =IF(D12=1,disposal_recovery,recov_yield) -> 0.9025 | E23: =IF(E12=1,disposal_recovery,recov_yield) -> 0.9025 | F23: =IF(F12=1,disposal_recovery,recov_yield) -> 0.9025 | G23: =IF(G12=1,disposal_recovery,recov_yield) -> 0.9025 | H23: =IF(H12=1,disposal_recovery,recov_yield) -> 0.2
A24: Credited secondary metal | B24: kg | C24: net scrap: recovered beyond recycled input | D24: =IF(ctx_credit="cut_off",0,d_mass*MAX(D23-recycled_content,0)) -> 7.23 | E24: =IF(ctx_credit="cut_off",0,d_mass*MAX(E23-recycled_content,0)) -> 7.23 | F24: =IF(ctx_credit="cut_off",0,d_mass*MAX(F23-recycled_content,0)) -> 7.23 | G24: =IF(ctx_credit="cut_off",0,d_mass*MAX(G23-recycled_content,0)) -> 7.23 | H24: =IF(ctx_credit="cut_off",0,d_mass*MAX(H23-recycled_content,0)) -> 0 | I24: Avoids double counting recycled input and EoL credit

Sheet LCI
A1: Life Cycle Inventory – foreground flows
A2: Amounts per panel life (rows 'per life') and per functional unit = one use (rows 'per FU'). Background datasets are indicative suggestions for Brightway/ecoinvent mapping – verify before use.
A4: Flow | B4: Unit | C4: Formula / note | D4: =Strategies!A2 -> reuse | E4: =Strategies!A3 -> repair | F4: =Strategies!A4 -> reprocessing | G4: =Strategies!A5 -> recycling | H4: =Strategies!A6 -> disposal | I4: Indicative background dataset (ecoinvent 3.x, verify)
A5: Per panel life (reference flow = 1 panel)
A6: A. Production (panel manufacture)
A7: Primary aluminium, ingot | B7: kg | C7: m × (1 − recycled content) | D7: =d_mass*(1-recycled_content) -> 8.4 | E7: =d_mass*(1-recycled_content) -> 8.4 | F7: =d_mass*(1-recycled_content) -> 8.4 | G7: =d_mass*(1-recycled_content) -> 8.4 | H7: =d_mass*(1-recycled_content) -> 8.4 | I7: market for aluminium, primary, ingot | IAI Area, EU27 & EFTA
A8: Secondary aluminium (post-consumer scrap) | B8: kg | C8: m × recycled content | D8: =d_mass*recycled_content -> 3.6 | E8: =d_mass*recycled_content -> 3.6 | F8: =d_mass*recycled_content -> 3.6 | G8: =d_mass*recycled_content -> 3.6 | H8: =d_mass*recycled_content -> 3.6 | I8: treatment of aluminium scrap, post-consumer, prepared for recycling, at remelter | RER
A9: Electricity, fabrication (cut, machine, finish) | B9: kWh | C9: m × e_fab × design factor | D9: =d_mass*e_fab*d_fab -> 20.7 | E9: =d_mass*e_fab*d_fab -> 20.7 | F9: =d_mass*e_fab*d_fab -> 20.7 | G9: =d_mass*e_fab*d_fab -> 20.7 | H9: =d_mass*e_fab*d_fab -> 20.7 | I9: market for electricity, low voltage | DE
A10: B. Use phase (events, maintenance)
A11: Road freight to and from events | B11: t·km | C11: U × legs × m/1000 × km | D11: =Calc!D18*Calc!D21*d_mass/1000*ctx_event_km -> 43.014049 | E11: =Calc!E18*Calc!E21*d_mass/1000*ctx_event_km -> 50.009503 | F11: =Calc!F18*Calc!F21*d_mass/1000*ctx_event_km -> 45.97683 | G11: =Calc!G18*Calc!G21*d_mass/1000*ctx_event_km -> 4.8 | H11: =Calc!H18*Calc!H21*d_mass/1000*ctx_event_km -> 4.8 | I11: market for transport, freight, lorry >32 metric ton, EURO6 | RER
A12: Electricity, cleaning and inspection | B12: kWh | C12: reuse routes, every event | D12: =IF(Calc!D6=1,0,Calc!D18*d_mass*e_clean) -> 2.6883781 | E12: =IF(Calc!E6=1,0,Calc!E18*d_mass*e_clean) -> 3.1255939 | F12: =IF(Calc!F6=1,0,Calc!F18*d_mass*e_clean) -> 2.8735518 | G12: =IF(Calc!G6=1,0,Calc!G18*d_mass*e_clean) -> 0 | H12: =IF(Calc!H6=1,0,Calc!H18*d_mass*e_clean) -> 0 | I12: market for electricity, low voltage | DE
A13: Electricity, reprocessing (strip, re-finish) | B13: kWh | C13: reprocessing route only | D13: =Calc!D18*d_mass*e_reprocess*Calc!D8 -> 0 | E13: =Calc!E18*d_mass*e_reprocess*Calc!E8 -> 0 | F13: =Calc!F18*d_mass*e_reprocess*Calc!F8 -> 45.97683 | G13: =Calc!G18*d_mass*e_reprocess*Calc!G8 -> 0 | H13: =Calc!H18*d_mass*e_reprocess*Calc!H8 -> 0 | I13: market for electricity, low voltage | DE
A14: Electricity, repair | B14: kWh | C14: repair route only | D14: =Calc!D18*Calc!D20*d_mass*e_repair -> 0 | E14: =Calc!E18*Calc!E20*d_mass*e_repair -> 1.2152309 | F14: =Calc!F18*Calc!F20*d_mass*e_repair -> 0 | G14: =Calc!G18*Calc!G20*d_mass*e_repair -> 0 | H14: =Calc!H18*Calc!H20*d_mass*e_repair -> 0 | I14: market for electricity, low voltage | DE
A15: Repair parts, primary aluminium | B15: kg | C15: replacement share × mass | D15: =Calc!D18*Calc!D20*d_mass*repair_share*(1-recycled_content) -> 0 | E15: =Calc!E18*Calc!E20*d_mass*repair_share*(1-recycled_content) -> 0.28355388 | F15: =Calc!F18*Calc!F20*d_mass*repair_share*(1-recycled_content) -> 0 | G15: =Calc!G18*Calc!G20*d_mass*repair_share*(1-recycled_content) -> 0 | H15: =Calc!H18*Calc!H20*d_mass*repair_share*(1-recycled_content) -> 0 | I15: market for aluminium, primary, ingot | IAI Area, EU27 & EFTA
A16: Repair parts, secondary aluminium | B16: kg | C16: replacement share × mass | D16: =Calc!D18*Calc!D20*d_mass*repair_share*recycled_content -> 0 | E16: =Calc!E18*Calc!E20*d_mass*repair_share*recycled_content -> 0.12152309 | F16: =Calc!F18*Calc!F20*d_mass*repair_share*recycled_content -> 0 | G16: =Calc!G18*Calc!G20*d_mass*repair_share*recycled_content -> 0 | H16: =Calc!H18*Calc!H20*d_mass*repair_share*recycled_content -> 0 | I16: treatment of aluminium scrap, post-consumer, prepared for recycling, at remelter | RER
A17: C. End of life
A18: Road freight to end-of-life facility | B18: t·km | C18: m/1000 × km | D18: =d_mass/1000*ctx_eol_km -> 1.2 | E18: =d_mass/1000*ctx_eol_km -> 1.2 | F18: =d_mass/1000*ctx_eol_km -> 1.2 | G18: =d_mass/1000*ctx_eol_km -> 1.2 | H18: =d_mass/1000*ctx_eol_km -> 1.2 | I18: market for transport, freight, lorry >32 metric ton, EURO6 | RER
A19: Electricity, dismantling and sorting | B19: kWh | C19: not for disposal | D19: =IF(Calc!D12=1,0,d_mass*sort_energy) -> 1.8 | E19: =IF(Calc!E12=1,0,d_mass*sort_energy) -> 1.8 | F19: =IF(Calc!F12=1,0,d_mass*sort_energy) -> 1.8 | G19: =IF(Calc!G12=1,0,d_mass*sort_energy) -> 1.8 | H19: =IF(Calc!H12=1,0,d_mass*sort_energy) -> 0 | I19: market for electricity, low voltage | DE
A20: Waste-to-energy treatment of aluminium | B20: kg | C20: disposal route only | D20: =IF(Calc!D12=1,d_mass,0) -> 0 | E20: =IF(Calc!E12=1,d_mass,0) -> 0 | F20: =IF(Calc!F12=1,d_mass,0) -> 0 | G20: =IF(Calc!G12=1,d_mass,0) -> 0 | H20: =IF(Calc!H12=1,d_mass,0) -> 12 | I20: treatment of waste aluminium, municipal incineration | CH
A21: D. Avoided burden (credit)
A22: Avoided primary aluminium (substituted by recovered metal) | B22: kg | C22: negative = avoided; 0 under cut-off | D22: =-Calc!D24 -> -7.23 | E22: =-Calc!E24 -> -7.23 | F22: =-Calc!F24 -> -7.23 | G22: =-Calc!G24 -> -7.23 | H22: =-Calc!H24 -> 0 | I22: −(primary ingot − secondary) | system expansion
A23: E. Outputs and memo flows (no direct GWP)
A24: Aluminium recovered to remelting / bottom-ash recovery | B24: kg | C24: m × recovery yield | D24: =d_mass*Calc!D23 -> 10.83 | E24: =d_mass*Calc!E23 -> 10.83 | F24: =d_mass*Calc!F23 -> 10.83 | G24: =d_mass*Calc!G23 -> 10.83 | H24: =d_mass*Calc!H23 -> 2.4 | I24: output to recycling
A25: Aluminium lost (slag, residues, uncollected) | B25: kg | C25: m × (1 − yield) | D25: =d_mass*(1-Calc!D23) -> 1.17 | E25: =d_mass*(1-Calc!E23) -> 1.17 | F25: =d_mass*(1-Calc!F23) -> 1.17 | G25: =d_mass*(1-Calc!G23) -> 1.17 | H25: =d_mass*(1-Calc!H23) -> 9.6 | I25: output to waste
A26: Panel discarded at end of life | B26: kg | C26: one panel | D26: =d_mass -> 12 | E26: =d_mass -> 12 | F26: =d_mass -> 12 | G26: =d_mass -> 12 | H26: =d_mass -> 12 | I26: reference flow mass
A27: Functional units delivered (expected uses U) | B27: uses | C27: link to Calc | D27: =Calc!D18 -> 4.4806301 | E27: =Calc!E18 -> 5.2093232 | F27: =Calc!F18 -> 4.7892531 | G27: =Calc!G18 -> 1 | H27: =Calc!H18 -> 1
A29: Per functional unit (one use of one panel) = per life ÷ U
A30: Primary aluminium, ingot | B30: kg | C30: per life ÷ U | D30: =D7/D27 -> 1.8747363 | E30: =E7/E27 -> 1.6124935 | F30: =F7/F27 -> 1.7539269 | G30: =G7/G27 -> 8.4 | H30: =H7/H27 -> 8.4 | I30: market for aluminium, primary, ingot | IAI Area, EU27 & EFTA
A31: Secondary aluminium (post-consumer scrap) | B31: kg | C31: per life ÷ U | D31: =D8/D27 -> 0.80345843 | E31: =E8/E27 -> 0.69106866 | F31: =F8/F27 -> 0.75168298 | G31: =G8/G27 -> 3.6 | H31: =H8/H27 -> 3.6 | I31: treatment of aluminium scrap, post-consumer, prepared for recycling, at remelter | RER
A32: Electricity, fabrication (cut, machine, finish) | B32: kWh | C32: per life ÷ U | D32: =D9/D27 -> 4.619886 | E32: =E9/E27 -> 3.9736448 | F32: =F9/F27 -> 4.3221771 | G32: =G9/G27 -> 20.7 | H32: =H9/H27 -> 20.7 | I32: market for electricity, low voltage | DE
A33: Road freight to and from events | B33: t·km | C33: per life ÷ U | D33: =D11/D27 -> 9.6 | E33: =E11/E27 -> 9.6 | F33: =F11/F27 -> 9.6 | G33: =G11/G27 -> 4.8 | H33: =H11/H27 -> 4.8 | I33: market for transport, freight, lorry >32 metric ton, EURO6 | RER
A34: Electricity, cleaning and inspection | B34: kWh | C34: per life ÷ U | D34: =D12/D27 -> 0.6 | E34: =E12/E27 -> 0.6 | F34: =F12/F27 -> 0.6 | G34: =G12/G27 -> 0 | H34: =H12/H27 -> 0 | I34: market for electricity, low voltage | DE
A35: Electricity, reprocessing (strip, re-finish) | B35: kWh | C35: per life ÷ U | D35: =D13/D27 -> 0 | E35: =E13/E27 -> 0 | F35: =F13/F27 -> 9.6 | G35: =G13/G27 -> 0 | H35: =H13/H27 -> 0 | I35: market for electricity, low voltage | DE
A36: Electricity, repair | B36: kWh | C36: per life ÷ U | D36: =D14/D27 -> 0 | E36: =E14/E27 -> 0.23328 | F36: =F14/F27 -> 0 | G36: =G14/G27 -> 0 | H36: =H14/H27 -> 0 | I36: market for electricity, low voltage | DE
A37: Repair parts, primary aluminium | B37: kg | C37: per life ÷ U | D37: =D15/D27 -> 0 | E37: =E15/E27 -> 0.054432 | F37: =F15/F27 -> 0 | G37: =G15/G27 -> 0 | H37: =H15/H27 -> 0 | I37: market for aluminium, primary, ingot | IAI Area, EU27 & EFTA
A38: Repair parts, secondary aluminium | B38: kg | C38: per life ÷ U | D38: =D16/D27 -> 0 | E38: =E16/E27 -> 0.023328 | F38: =F16/F27 -> 0 | G38: =G16/G27 -> 0 | H38: =H16/H27 -> 0 | I38: treatment of aluminium scrap, post-consumer, prepared for recycling, at remelter | RER
A39: Road freight to end-of-life facility | B39: t·km | C39: per life ÷ U | D39: =D18/D27 -> 0.26781948 | E39: =E18/E27 -> 0.23035622 | F39: =F18/F27 -> 0.25056099 | G39: =G18/G27 -> 1.2 | H39: =H18/H27 -> 1.2 | I39: market for transport, freight, lorry >32 metric ton, EURO6 | RER
A40: Electricity, dismantling and sorting | B40: kWh | C40: per life ÷ U | D40: =D19/D27 -> 0.40172921 | E40: =E19/E27 -> 0.34553433 | F40: =F19/F27 -> 0.37584149 | G40: =G19/G27 -> 1.8 | H40: =H19/H27 -> 0 | I40: market for electricity, low voltage | DE
A41: Waste-to-energy treatment of aluminium | B41: kg | C41: per life ÷ U | D41: =D20/D27 -> 0 | E41: =E20/E27 -> 0 | F41: =F20/F27 -> 0 | G41: =G20/G27 -> 0 | H41: =H20/H27 -> 12 | I41: treatment of waste aluminium, municipal incineration | CH
A42: Avoided primary aluminium (substituted by recovered metal) | B42: kg | C42: per life ÷ U | D42: =D22/D27 -> -1.6136123 | E42: =E22/E27 -> -1.3878962 | F42: =F22/F27 -> -1.50963 | G42: =G22/G27 -> -7.23 | H42: =H22/H27 -> 0 | I42: −(primary ingot − secondary) | system expansion
...

Sheet LCIA_GWP
A1: Impact assessment – climate change (GWP100)
A2: kg CO2e per functional unit (one use) = LCI per FU × emission factor. EF column links to Parameters / Context.
A4: Flow | B4: Unit | C4: Formula / note | D4: =Strategies!A2 -> reuse | E4: =Strategies!A3 -> repair | F4: =Strategies!A4 -> reprocessing | G4: =Strategies!A5 -> recycling | H4: =Strategies!A6 -> disposal | I4: Emission factor (kg CO2e/unit)
A5: GWP by flow (kg CO2e per use)
A6: Primary aluminium, ingot | B6: kg CO2e | C6: LCI per FU × ef_primary | D6: =LCI!D30*ef_primary -> 11.810839 | E6: =LCI!E30*ef_primary -> 10.158709 | F6: =LCI!F30*ef_primary -> 11.04974 | G6: =LCI!G30*ef_primary -> 52.92 | H6: =LCI!H30*ef_primary -> 52.92 | I6: =ef_primary -> 6.3
A7: Secondary aluminium (post-consumer scrap) | B7: kg CO2e | C7: LCI per FU × ef_secondary | D7: =LCI!D31*ef_secondary -> 0.40172921 | E7: =LCI!E31*ef_secondary -> 0.34553433 | F7: =LCI!F31*ef_secondary -> 0.37584149 | G7: =LCI!G31*ef_secondary -> 1.8 | H7: =LCI!H31*ef_secondary -> 1.8 | I7: =ef_secondary -> 0.5
A8: Electricity, fabrication (cut, machine, finish) | B8: kg CO2e | C8: LCI per FU × grid_ef | D8: =LCI!D32*grid_ef -> 1.5892408 | E8: =LCI!E32*grid_ef -> 1.3669338 | F8: =LCI!F32*grid_ef -> 1.4868289 | G8: =LCI!G32*grid_ef -> 7.1208 | H8: =LCI!H32*grid_ef -> 7.1208 | I8: =grid_ef -> 0.344
A9: Road freight to and from events | B9: kg CO2e | C9: LCI per FU × leg_ef | D9: =LCI!D33*leg_ef -> 0.928 | E9: =LCI!E33*leg_ef -> 0.928 | F9: =LCI!F33*leg_ef -> 0.928 | G9: =LCI!G33*leg_ef -> 0.464 | H9: =LCI!H33*leg_ef -> 0.464 | I9: =leg_ef -> 0.096666667
A10: Electricity, cleaning and inspection | B10: kg CO2e | C10: LCI per FU × grid_ef | D10: =LCI!D34*grid_ef -> 0.2064 | E10: =LCI!E34*grid_ef -> 0.2064 | F10: =LCI!F34*grid_ef -> 0.2064 | G10: =LCI!G34*grid_ef -> 0 | H10: =LCI!H34*grid_ef -> 0 | I10: =grid_ef -> 0.344
A11: Electricity, reprocessing (strip, re-finish) | B11: kg CO2e | C11: LCI per FU × grid_ef | D11: =LCI!D35*grid_ef -> 0 | E11: =LCI!E35*grid_ef -> 0 | F11: =LCI!F35*grid_ef -> 3.3024 | G11: =LCI!G35*grid_ef -> 0 | H11: =LCI!H35*grid_ef -> 0 | I11: =grid_ef -> 0.344
A12: Electricity, repair | B12: kg CO2e | C12: LCI per FU × grid_ef | D12: =LCI!D36*grid_ef -> 0 | E12: =LCI!E36*grid_ef -> 0.08024832 | F12: =LCI!F36*grid_ef -> 0 | G12: =LCI!G36*grid_ef -> 0 | H12: =LCI!H36*grid_ef -> 0 | I12: =grid_ef -> 0.344
A13: Repair parts, primary aluminium | B13: kg CO2e | C13: LCI per FU × ef_primary | D13: =LCI!D37*ef_primary -> 0 | E13: =LCI!E37*ef_primary -> 0.3429216 | F13: =LCI!F37*ef_primary -> 0 | G13: =LCI!G37*ef_primary -> 0 | H13: =LCI!H37*ef_primary -> 0 | I13: =ef_primary -> 6.3
A14: Repair parts, secondary aluminium | B14: kg CO2e | C14: LCI per FU × ef_secondary | D14: =LCI!D38*ef_secondary -> 0 | E14: =LCI!E38*ef_secondary -> 0.011664 | F14: =LCI!F38*ef_secondary -> 0 | G14: =LCI!G38*ef_secondary -> 0 | H14: =LCI!H38*ef_secondary -> 0 | I14: =ef_secondary -> 0.5
A15: Road freight to end-of-life facility | B15: kg CO2e | C15: LCI per FU × leg_ef | D15: =LCI!D39*leg_ef -> 0.025889216 | E15: =LCI!E39*leg_ef -> 0.022267768 | F15: =LCI!F39*leg_ef -> 0.024220896 | G15: =LCI!G39*leg_ef -> 0.116 | H15: =LCI!H39*leg_ef -> 0.116 | I15: =leg_ef -> 0.096666667
A16: Electricity, dismantling and sorting | B16: kg CO2e | C16: LCI per FU × grid_ef | D16: =LCI!D40*grid_ef -> 0.13819485 | E16: =LCI!E40*grid_ef -> 0.11886381 | F16: =LCI!F40*grid_ef -> 0.12928947 | G16: =LCI!G40*grid_ef -> 0.6192 | H16: =LCI!H40*grid_ef -> 0 | I16: =grid_ef -> 0.344
A17: Waste-to-energy treatment of aluminium | B17: kg CO2e | C17: LCI per FU × disposal_ef | D17: =LCI!D41*disposal_ef -> 0 | E17: =LCI!E41*disposal_ef -> 0 | F17: =LCI!F41*disposal_ef -> 0 | G17: =LCI!G41*disposal_ef -> 0 | H17: =LCI!H41*disposal_ef -> 0.24 | I17: =disposal_ef -> 0.02
A18: Avoided primary aluminium (substituted by recovered metal) | B18: kg CO2e | C18: LCI per FU × delta_ef | D18: =LCI!D42*delta_ef -> -9.3589516 | E18: =LCI!E42*delta_ef -> -8.0497981 | F18: =LCI!F42*delta_ef -> -8.7558539 | G18: =LCI!G42*delta_ef -> -41.934 | H18: =LCI!H42*delta_ef -> 0 | I18: =delta_ef -> 5.8
A19: GWP by life-cycle stage (kg CO2e per use)
A20: Panel production | B20: kg CO2e | C20: sum of stage flows | D20: =D6+D7+D8 -> 13.801809 | E20: =E6+E7+E8 -> 11.871177 | F20: =F6+F7+F8 -> 12.91241 | G20: =G6+G7+G8 -> 61.8408 | H20: =H6+H7+H8 -> 61.8408
A21: Use phase (transport, cleaning, repair, reprocessing) | B21: kg CO2e | C21: sum of stage flows | D21: =D9+D10+D11+D12+D13+D14 -> 1.1344 | E21: =E9+E10+E11+E12+E13+E14 -> 1.5692339 | F21: =F9+F10+F11+F12+F13+F14 -> 4.4368 | G21: =G9+G10+G11+G12+G13+G14 -> 0.464 | H21: =H9+H10+H11+H12+H13+H14 -> 0.464
A22: End-of-life processes | B22: kg CO2e | C22: sum of stage flows | D22: =D15+D16+D17 -> 0.16408407 | E22: =E15+E16+E17 -> 0.14113158 | F22: =F15+F16+F17 -> 0.15351037 | G22: =G15+G16+G17 -> 0.7352 | H22: =H15+H16+H17 -> 0.356
A23: Recycling credit | B23: kg CO2e | C23: sum of stage flows | D23: =D18 -> -9.3589516 | E23: =E18 -> -8.0497981 | F23: =F18 -> -8.7558539 | G23: =G18 -> -41.934 | H23: =H18 -> 0
A24: Total climate impact per use | B24: kg CO2e/use | D24: =D20+D21+D22+D23 -> 5.7413413 | E24: =E20+E21+E22+E23 -> 5.5317448 | F24: =F20+F21+F22+F23 -> 8.7468667 | G24: =G20+G21+G22+G23 -> 21.106 | H24: =H20+H21+H22+H23 -> 62.6608
A25: Total climate impact per panel life | B25: kg CO2e | D25: =D24*Calc!D18 -> 25.724827 | E25: =E24*Calc!E18 -> 28.816647 | F25: =F24*Calc!F18 -> 41.890958 | G25: =G24*Calc!G18 -> 21.106 | H25: =H24*Calc!H18 -> 62.6608
A26: Stage shares of gross burden (excl. credit)
A27: Panel production | B27: share | D27: =IF((D20+D21+D22)=0,0,D20/(D20+D21+D22)) -> 0.91400935 | E27: =IF((E20+E21+E22)=0,0,E20/(E20+E21+E22)) -> 0.87406692 | F27: =IF((F20+F21+F22)=0,0,F20/(F20+F21+F22)) -> 0.73773732 | G27: =IF((G20+G21+G22)=0,0,G20/(G20+G21+G22)) -> 0.98097716 | H27: =IF((H20+H21+H22)=0,0,H20/(H20+H21+H22)) -> 0.98691367
A28: Use phase (transport, cleaning, repair, reprocessing) | B28: share | D28: =IF((D20+D21+D22)=0,0,D21/(D20+D21+D22)) -> 0.075124371 | E28: =IF((E20+E21+E22)=0,0,E21/(E20+E21+E22)) -> 0.11554165 | F28: =IF((F20+F21+F22)=0,0,F21/(F20+F21+F22)) -> 0.25349202 | G28: =IF((G20+G21+G22)=0,0,G21/(G20+G21+G22)) -> 0.0073604061 | H28: =IF((H20+H21+H22)=0,0,H21/(H20+H21+H22)) -> 0.0074049485
A29: End-of-life processes | B29: share | D29: =IF((D20+D21+D22)=0,0,D22/(D20+D21+D22)) -> 0.010866284 | E29: =IF((E20+E21+E22)=0,0,E22/(E20+E21+E22)) -> 0.010391424 | F29: =IF((F20+F21+F22)=0,0,F22/(F20+F21+F22)) -> 0.0087706575 | G29: =IF((G20+G21+G22)=0,0,G22/(G20+G21+G22)) -> 0.011662437 | H29: =IF((H20+H21+H22)=0,0,H22/(H20+H21+H22)) -> 0.0056813829

Sheet Cost
A1: Cost inventory (EUR proxy)
A2: Per panel life; negative = revenue. Per-use cost includes the business-model margin.
A4: Cost item | B4: Unit | C4: Formula / note | D4: =Strategies!A2 -> reuse | E4: =Strategies!A3 -> repair | F4: =Strategies!A4 -> reprocessing | G4: =Strategies!A5 -> recycling | H4: =Strategies!A6 -> disposal | I4: Basis / source
A5: Per panel life (EUR)
A6: Panel purchase (metal + manufacturing) | B6: EUR | C6: m × (Al price + manuf. cost × factor) | D6: =d_mass*(price_kg+manuf_cost*d_cost) -> 139.08 | E6: =d_mass*(price_kg+manuf_cost*d_cost) -> 139.08 | F6: =d_mass*(price_kg+manuf_cost*d_cost) -> 139.08 | G6: =d_mass*(price_kg+manuf_cost*d_cost) -> 139.08 | H6: =d_mass*(price_kg+manuf_cost*d_cost) -> 139.08
A7: Freight to and from events | B7: EUR | D7: =Calc!D18*Calc!D21*d_mass/1000*ctx_event_km*transport_cost -> 10.753512 | E7: =Calc!E18*Calc!E21*d_mass/1000*ctx_event_km*transport_cost -> 12.502376 | F7: =Calc!F18*Calc!F21*d_mass/1000*ctx_event_km*transport_cost -> 11.494207 | G7: =Calc!G18*Calc!G21*d_mass/1000*ctx_event_km*transport_cost -> 1.2 | H7: =Calc!H18*Calc!H21*d_mass/1000*ctx_event_km*transport_cost -> 1.2
A8: Set-up and dismantling labour | B8: EUR | D8: =Calc!D18*handling_cost -> 26.883781 | E8: =Calc!E18*handling_cost -> 31.255939 | F8: =Calc!F18*handling_cost -> 28.735518 | G8: =Calc!G18*handling_cost -> 6 | H8: =Calc!H18*handling_cost -> 6
A9: Storage between events | B9: EUR | C9: reuse routes | D9: =IF(Calc!D6=1,0,Calc!D18*storage_cost) -> 13.44189 | E9: =IF(Calc!E6=1,0,Calc!E18*storage_cost) -> 15.62797 | F9: =IF(Calc!F6=1,0,Calc!F18*storage_cost) -> 14.367759 | G9: =IF(Calc!G6=1,0,Calc!G18*storage_cost) -> 0 | H9: =IF(Calc!H6=1,0,Calc!H18*storage_cost) -> 0
A10: Workshop labour (inspect, repair, reprocess) | B10: EUR | C10: repair: labour per repair + 0.05 h inspection | D10: =IF(Calc!D6=1,0,Calc!D18*(Calc!D10*labour_rate*IF(Calc!D7=1,Calc!D20,1)+IF(Calc!D7=1,0.05*labour_rate,0))) -> 10.081418 | E10: =IF(Calc!E6=1,0,Calc!E18*(Calc!E10*labour_rate*IF(Calc!E7=1,Calc!E20,1)+IF(Calc!E7=1,0.05*labour_rate,0))) -> 17.797132 | F10: =IF(Calc!F6=1,0,Calc!F18*(Calc!F10*labour_rate*IF(Calc!F7=1,Calc!F20,1)+IF(Calc!F7=1,0.05*labour_rate,0))) -> 53.879097 | G10: =IF(Calc!G6=1,0,Calc!G18*(Calc!G10*labour_rate*IF(Calc!G7=1,Calc!G20,1)+IF(Calc!G7=1,0.05*labour_rate,0))) -> 0 | H10: =IF(Calc!H6=1,0,Calc!H18*(Calc!H10*labour_rate*IF(Calc!H7=1,Calc!H20,1)+IF(Calc!H7=1,0.05*labour_rate,0))) -> 0
A11: Repair material | B11: EUR | D11: =Calc!D18*Calc!D20*repair_share*d_mass*(price_kg+manuf_cost*d_cost) -> 0 | E11: =Calc!E18*Calc!E20*repair_share*d_mass*(price_kg+manuf_cost*d_cost) -> 4.6948421 | F11: =Calc!F18*Calc!F20*repair_share*d_mass*(price_kg+manuf_cost*d_cost) -> 0 | G11: =Calc!G18*Calc!G20*repair_share*d_mass*(price_kg+manuf_cost*d_cost) -> 0 | H11: =Calc!H18*Calc!H20*repair_share*d_mass*(price_kg+manuf_cost*d_cost) -> 0
A12: Freight to end-of-life | B12: EUR | D12: =d_mass/1000*ctx_eol_km*transport_cost -> 0.3 | E12: =d_mass/1000*ctx_eol_km*transport_cost -> 0.3 | F12: =d_mass/1000*ctx_eol_km*transport_cost -> 0.3 | G12: =d_mass/1000*ctx_eol_km*transport_cost -> 0.3 | H12: =d_mass/1000*ctx_eol_km*transport_cost -> 0.3
A13: Scrap revenue | B13: EUR | C13: revenue (negative) | D13: =IF(Calc!D12=1,0,-d_mass*Calc!D23*price_kg*scrap_price_ratio) -> -21.15099 | E13: =IF(Calc!E12=1,0,-d_mass*Calc!E23*price_kg*scrap_price_ratio) -> -21.15099 | F13: =IF(Calc!F12=1,0,-d_mass*Calc!F23*price_kg*scrap_price_ratio) -> -21.15099 | G13: =IF(Calc!G12=1,0,-d_mass*Calc!G23*price_kg*scrap_price_ratio) -> -21.15099 | H13: =IF(Calc!H12=1,0,-d_mass*Calc!H23*price_kg*scrap_price_ratio) -> 0
A14: Disposal gate fee | B14: EUR | D14: =IF(Calc!D12=1,d_mass*gate_fee,0) -> 0 | E14: =IF(Calc!E12=1,d_mass*gate_fee,0) -> 0 | F14: =IF(Calc!F12=1,d_mass*gate_fee,0) -> 0 | G14: =IF(Calc!G12=1,d_mass*gate_fee,0) -> 0 | H14: =IF(Calc!H12=1,d_mass*gate_fee,0) -> 1.8
A15: Total cost per panel life | B15: EUR | D15: =SUM(D6:D14) -> 179.38961 | E15: =SUM(E6:E14) -> 200.10727 | F15: =SUM(F6:F14) -> 226.70559 | G15: =SUM(G6:G14) -> 125.42901 | H15: =SUM(H6:H14) -> 148.38
A16: Cost per use (incl. margin) | B16: EUR/use | D16: =D15/Calc!D18*(1+bm_margin) -> 48.044031 | E16: =E15/Calc!E18*(1+bm_margin) -> 46.095954 | F16: =F15/Calc!F18*(1+bm_margin) -> 56.803578 | G16: =G15/Calc!G18*(1+bm_margin) -> 150.51481 | H16: =H15/Calc!H18*(1+bm_margin) -> 178.056

Sheet KPIs
A1: Circularity and sustainability KPIs
A2: All values per use unless stated. Weighted score = 0.50 environment + 0.25 circularity + 0.15 economics + 0.10 feasibility (edit weights below).
A4: KPI | B4: Unit | C4: Formula / note | D4: =Strategies!A2 -> reuse | E4: =Strategies!A3 -> repair | F4: =Strategies!A4 -> reprocessing | G4: =Strategies!A5 -> recycling | H4: =Strategies!A6 -> disposal | I4: Basis / source
A5: Core KPIs
A6: Expected uses | B6: uses | D6: =Calc!D18 -> 4.4806301 | E6: =Calc!E18 -> 5.2093232 | F6: =Calc!F18 -> 4.7892531 | G6: =Calc!G18 -> 1 | H6: =Calc!H18 -> 1
A7: Reuse cycles | B7: cycles | D7: =Calc!D19 -> 3.4806301 | E7: =Calc!E19 -> 4.2093232 | F7: =Calc!F19 -> 3.7892531 | G7: =Calc!G19 -> 0 | H7: =Calc!H19 -> 0
A8: Climate impact per use | B8: kg CO2e/use | C8: from LCIA_GWP | D8: =LCIA_GWP!D24 -> 5.7413413 | E8: =LCIA_GWP!E24 -> 5.5317448 | F8: =LCIA_GWP!F24 -> 8.7468667 | G8: =LCIA_GWP!G24 -> 21.106 | H8: =LCIA_GWP!H24 -> 62.6608
A9: Cost per use | B9: EUR/use | C9: from Cost | D9: =Cost!D16 -> 48.044031 | E9: =Cost!E16 -> 46.095954 | F9: =Cost!F16 -> 56.803578 | G9: =Cost!G16 -> 150.51481 | H9: =Cost!H16 -> 178.056
A10: Virgin feedstock V | B10: kg | C10: MCI input | D10: =d_mass*(1-recycled_content) -> 8.4 | E10: =d_mass*(1-recycled_content) -> 8.4 | F10: =d_mass*(1-recycled_content) -> 8.4 | G10: =d_mass*(1-recycled_content) -> 8.4 | H10: =d_mass*(1-recycled_content) -> 8.4
A11: Unrecoverable waste W | B11: kg | C11: MCI input | D11: =d_mass*(1-Calc!D23) -> 1.17 | E11: =d_mass*(1-Calc!E23) -> 1.17 | F11: =d_mass*(1-Calc!F23) -> 1.17 | G11: =d_mass*(1-Calc!G23) -> 1.17 | H11: =d_mass*(1-Calc!H23) -> 9.6
A12: Linear flow index LFI | B12: – | C12: (V + W) / 2M | D12: =(D10+D11)/(2*d_mass) -> 0.39875 | E12: =(E10+E11)/(2*d_mass) -> 0.39875 | F12: =(F10+F11)/(2*d_mass) -> 0.39875 | G12: =(G10+G11)/(2*d_mass) -> 0.39875 | H12: =(H10+H11)/(2*d_mass) -> 0.75
A13: Circularity (simplified MCI) | B13: 0–1 | C13: 1 − LFI × 0.9 / utility; utility = U | D13: =MAX(0,1-D12*0.9/MAX(Calc!D18,1)) -> 0.91990524 | E13: =MAX(0,1-E12*0.9/MAX(Calc!E18,1)) -> 0.93110909 | F13: =MAX(0,1-F12*0.9/MAX(Calc!F18,1)) -> 0.9250666 | G13: =MAX(0,1-G12*0.9/MAX(Calc!G18,1)) -> 0.641125 | H13: =MAX(0,1-H12*0.9/MAX(Calc!H18,1)) -> 0.325 | I13: Ellen MacArthur Foundation (2015) MCI, simplified: utility = expected uses
A14: Material recovery | B14: share | D14: =Calc!D23 -> 0.9025 | E14: =Calc!E23 -> 0.9025 | F14: =Calc!F23 -> 0.9025 | G14: =Calc!G23 -> 0.9025 | H14: =Calc!H23 -> 0.2
A15: Net virgin aluminium per use | B15: kg/use | D15: =MAX(d_mass*(1-recycled_content)-Calc!D24,0)/Calc!D18 -> 0.26112399 | E15: =MAX(d_mass*(1-recycled_content)-Calc!E24,0)/Calc!E18 -> 0.22459732 | F15: =MAX(d_mass*(1-recycled_content)-Calc!F24,0)/Calc!F18 -> 0.24429697 | G15: =MAX(d_mass*(1-recycled_content)-Calc!G24,0)/Calc!G18 -> 1.17 | H15: =MAX(d_mass*(1-recycled_content)-Calc!H24,0)/Calc!H18 -> 8.4
A16: Design suitability | B16: 0–1 | D16: =IF(Calc!D6=1,1,IF(Calc!D7=1,0.5+0.5*d_repair,0.5+0.5*d_disasm)) -> 0.95 | E16: =IF(Calc!E6=1,1,IF(Calc!E7=1,0.5+0.5*d_repair,0.5+0.5*d_disasm)) -> 0.95 | F16: =IF(Calc!F6=1,1,IF(Calc!F7=1,0.5+0.5*d_repair,0.5+0.5*d_disasm)) -> 0.95 | G16: =IF(Calc!G6=1,1,IF(Calc!G7=1,0.5+0.5*d_repair,0.5+0.5*d_disasm)) -> 1 | H16: =IF(Calc!H6=1,1,IF(Calc!H7=1,0.5+0.5*d_repair,0.5+0.5*d_disasm)) -> 1
A17: Organisational reliability | B17: 0–1 | D17: =IF(Calc!D6=1,1,0.6+0.4*bm_redeploy) -> 0.98 | E17: =IF(Calc!E6=1,1,0.6+0.4*bm_redeploy) -> 0.98 | F17: =IF(Calc!F6=1,1,0.6+0.4*bm_redeploy) -> 0.98 | G17: =IF(Calc!G6=1,1,0.6+0.4*bm_redeploy) -> 1 | H17: =IF(Calc!H6=1,1,0.6+0.4*bm_redeploy) -> 1
A18: Feasibility | B18: 0–1 | C18: base × suitability × distance × organisation | D18: =Calc!D11*D16*dist_factor*D17 -> 0.63308 | E18: =Calc!E11*E16*dist_factor*E17 -> 0.5586 | F18: =Calc!F11*F16*dist_factor*F17 -> 0.48412 | G18: =Calc!G11*G16*dist_factor*G17 -> 0.72 | H18: =Calc!H11*H16*dist_factor*H17 -> 0.8
A20: Weights (edit)
A21: Weight – environment | D21: 0.5
A22: Weight – circularity | D22: 0.25
A23: Weight – economics | D23: 0.15
A24: Weight – feasibility | D24: 0.1
A25: Normalised criteria and weighted score
A26: Environment (min–max, lower GWP better) | B26: 0–1 | D26: =IF(MAX($D$8:$H$8)-MIN($D$8:$H$8)<0.000000000001,0.5,1-(D8-MIN($D$8:$H$8))/(MAX($D$8:$H$8)-MIN($D$8:$H$8))) -> 0.99633118 | E26: =IF(MAX($D$8:$H$8)-MIN($D$8:$H$8)<0.000000000001,0.5,1-(E8-MIN($D$8:$H$8))/(MAX($D$8:$H$8)-MIN($D$8:$H$8))) -> 1 | F26: =IF(MAX($D$8:$H$8)-MIN($D$8:$H$8)<0.000000000001,0.5,1-(F8-MIN($D$8:$H$8))/(MAX($D$8:$H$8)-MIN($D$8:$H$8))) -> 0.94372178 | G26: =IF(MAX($D$8:$H$8)-MIN($D$8:$H$8)<0.000000000001,0.5,1-(G8-MIN($D$8:$H$8))/(MAX($D$8:$H$8)-MIN($D$8:$H$8))) -> 0.72738469 | H26: =IF(MAX($D$8:$H$8)-MIN($D$8:$H$8)<0.000000000001,0.5,1-(H8-MIN($D$8:$H$8))/(MAX($D$8:$H$8)-MIN($D$8:$H$8))) -> 0
A27: Circularity | B27: 0–1 | D27: =MIN(1,MAX(0,D13)) -> 0.91990524 | E27: =MIN(1,MAX(0,E13)) -> 0.93110909 | F27: =MIN(1,MAX(0,F13)) -> 0.9250666 | G27: =MIN(1,MAX(0,G13)) -> 0.641125 | H27: =MIN(1,MAX(0,H13)) -> 0.325
A28: Economics (min–max, lower cost better) | B28: 0–1 | D28: =IF(MAX($D$9:$H$9)-MIN($D$9:$H$9)<0.000000000001,0.5,1-(D9-MIN($D$9:$H$9))/(MAX($D$9:$H$9)-MIN($D$9:$H$9))) -> 0.98523737 | E28: =IF(MAX($D$9:$H$9)-MIN($D$9:$H$9)<0.000000000001,0.5,1-(E9-MIN($D$9:$H$9))/(MAX($D$9:$H$9)-MIN($D$9:$H$9))) -> 1 | F28: =IF(MAX($D$9:$H$9)-MIN($D$9:$H$9)<0.000000000001,0.5,1-(F9-MIN($D$9:$H$9))/(MAX($D$9:$H$9)-MIN($D$9:$H$9))) -> 0.91885708 | G28: =IF(MAX($D$9:$H$9)-MIN($D$9:$H$9)<0.000000000001,0.5,1-(G9-MIN($D$9:$H$9))/(MAX($D$9:$H$9)-MIN($D$9:$H$9))) -> 0.20870854 | H28: =IF(MAX($D$9:$H$9)-MIN($D$9:$H$9)<0.000000000001,0.5,1-(H9-MIN($D$9:$H$9))/(MAX($D$9:$H$9)-MIN($D$9:$H$9))) -> 0
A29: Feasibility | B29: 0–1 | D29: =MIN(1,MAX(0,D18)) -> 0.63308 | E29: =MIN(1,MAX(0,E18)) -> 0.5586 | F29: =MIN(1,MAX(0,F18)) -> 0.48412 | G29: =MIN(1,MAX(0,G18)) -> 0.72 | H29: =MIN(1,MAX(0,H18)) -> 0.8
A30: Weighted score | B30: 0–1 | D30: =(D26*w_environment+D27*w_circularity+D28*w_economics+D29*w_feasibility)/(w_environment+w_circularity+w_economics+w_feasibility) -> 0.9392355 | E30: =(E26*w_environment+E27*w_circularity+E28*w_economics+E29*w_feasibility)/(w_environment+w_circularity+w_economics+w_feasibility) -> 0.93863727 | F30: =(F26*w_environment+F27*w_circularity+F28*w_economics+F29*w_feasibility)/(w_environment+w_circularity+w_economics+w_feasibility) -> 0.8893681 | G30: =(G26*w_environment+G27*w_circularity+G28*w_economics+G29*w_feasibility)/(w_environment+w_circularity+w_economics+w_feasibility) -> 0.62727987 | H30: =(H26*w_environment+H27*w_circularity+H28*w_economics+H29*w_feasibility)/(w_environment+w_circularity+w_economics+w_feasibility) -> 0.16125
A31: Rank | B31: # | D31: =RANK(D30,$D$30:$H$30,0) -> 1 | E31: =RANK(E30,$D$30:$H$30,0) -> 2 | F31: =RANK(F30,$D$30:$H$30,0) -> 3 | G31: =RANK(G30,$D$30:$H$30,0) -> 4 | H31: =RANK(H30,$D$30:$H$30,0) -> 5
A33: Recommended strategy (highest score) | D33: =INDEX($D$4:$H$4,MATCH(MAX($D$30:$H$30),$D$30:$H$30,0)) -> reuse
A34: Lowest climate impact per use | D34: =INDEX($D$4:$H$4,MATCH(MIN($D$8:$H$8),$D$8:$H$8,0)) -> repair

Sheet Validation
A1: Validation against the Python model
A2: Reference = src/cirdesign/model.py evaluated at the default context B/rental/6 uses/400 km/net_scrap when this file was built. If you change Context or Parameters the reference no longer applies.
A4: KPI | B4: Strategy | C4: Python reference | D4: Excel | E4: Abs. difference | F4: Status
A5: Expected uses | B5: reuse | C5: 4.4806301 | D5: =KPIs!D6 -> 4.4806301 | E5: =ABS(D5-C5) -> 0 | F5: =IF(E5<=0.000001*MAX(1,ABS(C5)),"OK","CHECK") -> OK
A6: Expected uses | B6: repair | C6: 5.2093232 | D6: =KPIs!E6 -> 5.2093232 | E6: =ABS(D6-C6) -> 0 | F6: =IF(E6<=0.000001*MAX(1,ABS(C6)),"OK","CHECK") -> OK
A7: Expected uses | B7: reprocessing | C7: 4.7892531 | D7: =KPIs!F6 -> 4.7892531 | E7: =ABS(D7-C7) -> 0 | F7: =IF(E7<=0.000001*MAX(1,ABS(C7)),"OK","CHECK") -> OK
A8: Expected uses | B8: recycling | C8: 1 | D8: =KPIs!G6 -> 1 | E8: =ABS(D8-C8) -> 0 | F8: =IF(E8<=0.000001*MAX(1,ABS(C8)),"OK","CHECK") -> OK
A9: Expected uses | B9: disposal | C9: 1 | D9: =KPIs!H6 -> 1 | E9: =ABS(D9-C9) -> 0 | F9: =IF(E9<=0.000001*MAX(1,ABS(C9)),"OK","CHECK") -> OK
A10: Climate per use (kg CO2e) | B10: reuse | C10: 5.7413413 | D10: =KPIs!D8 -> 5.7413413 | E10: =ABS(D10-C10) -> 0 | F10: =IF(E10<=0.000001*MAX(1,ABS(C10)),"OK","CHECK") -> OK
A11: Climate per use (kg CO2e) | B11: repair | C11: 5.5317448 | D11: =KPIs!E8 -> 5.5317448 | E11: =ABS(D11-C11) -> 0 | F11: =IF(E11<=0.000001*MAX(1,ABS(C11)),"OK","CHECK") -> OK
A12: Climate per use (kg CO2e) | B12: reprocessing | C12: 8.7468667 | D12: =KPIs!F8 -> 8.7468667 | E12: =ABS(D12-C12) -> 0 | F12: =IF(E12<=0.000001*MAX(1,ABS(C12)),"OK","CHECK") -> OK
A13: Climate per use (kg CO2e) | B13: recycling | C13: 21.106 | D13: =KPIs!G8 -> 21.106 | E13: =ABS(D13-C13) -> 0 | F13: =IF(E13<=0.000001*MAX(1,ABS(C13)),"OK","CHECK") -> OK
A14: Climate per use (kg CO2e) | B14: disposal | C14: 62.6608 | D14: =KPIs!H8 -> 62.6608 | E14: =ABS(D14-C14) -> 0 | F14: =IF(E14<=0.000001*MAX(1,ABS(C14)),"OK","CHECK") -> OK
A15: Cost per use (EUR) | B15: reuse | C15: 48.044031 | D15: =KPIs!D9 -> 48.044031 | E15: =ABS(D15-C15) -> 0 | F15: =IF(E15<=0.000001*MAX(1,ABS(C15)),"OK","CHECK") -> OK
A16: Cost per use (EUR) | B16: repair | C16: 46.095954 | D16: =KPIs!E9 -> 46.095954 | E16: =ABS(D16-C16) -> 0 | F16: =IF(E16<=0.000001*MAX(1,ABS(C16)),"OK","CHECK") -> OK
A17: Cost per use (EUR) | B17: reprocessing | C17: 56.803578 | D17: =KPIs!F9 -> 56.803578 | E17: =ABS(D17-C17) -> 0 | F17: =IF(E17<=0.000001*MAX(1,ABS(C17)),"OK","CHECK") -> OK
A18: Cost per use (EUR) | B18: recycling | C18: 150.51481 | D18: =KPIs!G9 -> 150.51481 | E18: =ABS(D18-C18) -> 0 | F18: =IF(E18<=0.000001*MAX(1,ABS(C18)),"OK","CHECK") -> OK
A19: Cost per use (EUR) | B19: disposal | C19: 178.056 | D19: =KPIs!H9 -> 178.056 | E19: =ABS(D19-C19) -> 0 | F19: =IF(E19<=0.000001*MAX(1,ABS(C19)),"OK","CHECK") -> OK
A20: Circularity (MCI) | B20: reuse | C20: 0.91990524 | D20: =KPIs!D13 -> 0.91990524 | E20: =ABS(D20-C20) -> 0 | F20: =IF(E20<=0.000001*MAX(1,ABS(C20)),"OK","CHECK") -> OK
A21: Circularity (MCI) | B21: repair | C21: 0.93110909 | D21: =KPIs!E13 -> 0.93110909 | E21: =ABS(D21-C21) -> 0 | F21: =IF(E21<=0.000001*MAX(1,ABS(C21)),"OK","CHECK") -> OK
A22: Circularity (MCI) | B22: reprocessing | C22: 0.9250666 | D22: =KPIs!F13 -> 0.9250666 | E22: =ABS(D22-C22) -> 0 | F22: =IF(E22<=0.000001*MAX(1,ABS(C22)),"OK","CHECK") -> OK
A23: Circularity (MCI) | B23: recycling | C23: 0.641125 | D23: =KPIs!G13 -> 0.641125 | E23: =ABS(D23-C23) -> 0 | F23: =IF(E23<=0.000001*MAX(1,ABS(C23)),"OK","CHECK") -> OK
A24: Circularity (MCI) | B24: disposal | C24: 0.325 | D24: =KPIs!H13 -> 0.325 | E24: =ABS(D24-C24) -> 0 | F24: =IF(E24<=0.000001*MAX(1,ABS(C24)),"OK","CHECK") -> OK
A25: Material recovery | B25: reuse | C25: 0.9025 | D25: =KPIs!D14 -> 0.9025 | E25: =ABS(D25-C25) -> 0 | F25: =IF(E25<=0.000001*MAX(1,ABS(C25)),"OK","CHECK") -> OK
A26: Material recovery | B26: repair | C26: 0.9025 | D26: =KPIs!E14 -> 0.9025 | E26: =ABS(D26-C26) -> 0 | F26: =IF(E26<=0.000001*MAX(1,ABS(C26)),"OK","CHECK") -> OK
A27: Material recovery | B27: reprocessing | C27: 0.9025 | D27: =KPIs!F14 -> 0.9025 | E27: =ABS(D27-C27) -> 0 | F27: =IF(E27<=0.000001*MAX(1,ABS(C27)),"OK","CHECK") -> OK
A28: Material recovery | B28: recycling | C28: 0.9025 | D28: =KPIs!G14 -> 0.9025 | E28: =ABS(D28-C28) -> 0 | F28: =IF(E28<=0.000001*MAX(1,ABS(C28)),"OK","CHECK") -> OK
A29: Material recovery | B29: disposal | C29: 0.2 | D29: =KPIs!H14 -> 0.2 | E29: =ABS(D29-C29) -> 0 | F29: =IF(E29<=0.000001*MAX(1,ABS(C29)),"OK","CHECK") -> OK
A30: Virgin Al per use (kg) | B30: reuse | C30: 0.26112399 | D30: =KPIs!D15 -> 0.26112399 | E30: =ABS(D30-C30) -> 0 | F30: =IF(E30<=0.000001*MAX(1,ABS(C30)),"OK","CHECK") -> OK
A31: Virgin Al per use (kg) | B31: repair | C31: 0.22459732 | D31: =KPIs!E15 -> 0.22459732 | E31: =ABS(D31-C31) -> 0 | F31: =IF(E31<=0.000001*MAX(1,ABS(C31)),"OK","CHECK") -> OK
A32: Virgin Al per use (kg) | B32: reprocessing | C32: 0.24429697 | D32: =KPIs!F15 -> 0.24429697 | E32: =ABS(D32-C32) -> 0 | F32: =IF(E32<=0.000001*MAX(1,ABS(C32)),"OK","CHECK") -> OK
A33: Virgin Al per use (kg) | B33: recycling | C33: 1.17 | D33: =KPIs!G15 -> 1.17 | E33: =ABS(D33-C33) -> 0 | F33: =IF(E33<=0.000001*MAX(1,ABS(C33)),"OK","CHECK") -> OK
A34: Virgin Al per use (kg) | B34: disposal | C34: 8.4 | D34: =KPIs!H15 -> 8.4 | E34: =ABS(D34-C34) -> 0 | F34: =IF(E34<=0.000001*MAX(1,ABS(C34)),"OK","CHECK") -> OK
A35: Feasibility | B35: reuse | C35: 0.63308 | D35: =KPIs!D18 -> 0.63308 | E35: =ABS(D35-C35) -> 0 | F35: =IF(E35<=0.000001*MAX(1,ABS(C35)),"OK","CHECK") -> OK
A36: Feasibility | B36: repair | C36: 0.5586 | D36: =KPIs!E18 -> 0.5586 | E36: =ABS(D36-C36) -> 0 | F36: =IF(E36<=0.000001*MAX(1,ABS(C36)),"OK","CHECK") -> OK
A37: Feasibility | B37: reprocessing | C37: 0.48412 | D37: =KPIs!F18 -> 0.48412 | E37: =ABS(D37-C37) -> 0 | F37: =IF(E37<=0.000001*MAX(1,ABS(C37)),"OK","CHECK") -> OK
A38: Feasibility | B38: recycling | C38: 0.72 | D38: =KPIs!G18 -> 0.72 | E38: =ABS(D38-C38) -> 0 | F38: =IF(E38<=0.000001*MAX(1,ABS(C38)),"OK","CHECK") -> OK
A39: Feasibility | B39: disposal | C39: 0.8 | D39: =KPIs!H18 -> 0.8 | E39: =ABS(D39-C39) -> 0 | F39: =IF(E39<=0.000001*MAX(1,ABS(C39)),"OK","CHECK") -> OK
A40: Weighted score | B40: reuse | C40: 0.9392355 | D40: =KPIs!D30 -> 0.9392355 | E40: =ABS(D40-C40) -> 0 | F40: =IF(E40<=0.000001*MAX(1,ABS(C40)),"OK","CHECK") -> OK
